<?xml version='1.0'?>
<sdf version='1.7'>
  <model name='racecar'>
    <link name='base_link'>
      <inertial>
        <pose>0.1477 0 0.05 0 -0 0</pose>
        <mass>4</mass>
        <inertia>
          <ixx>0.010609</ixx>
          <ixy>0</ixy>
          <ixz>0</ixz>
          <iyy>0.050409</iyy>
          <iyz>0</iyz>
          <izz>0.05865</izz>
        </inertia>
      </inertial>
      <visual name='base_link_fixed_joint_lump__chassis_visual'>
        <pose>0 0 0.05 0 -0 0</pose>
        <geometry>
          <mesh>
            <scale>1 1 1</scale>
            <uri>model://src_ackermann/meshes/chassis.STL</uri>
          </mesh>
        </geometry>
      </visual>
    </link>
    <joint name='hokuyo_joint' type='fixed'>
      <pose relative_to='base_link'>0.265 0 0.125 0 -0 0</pose>
      <parent>base_link</parent>
      <child>laser</child>
      <axis>
        <xyz>0 0 1</xyz>
        <limit>
          <lower>-1e+16</lower>
          <upper>1e+16</upper>
        </limit>
        <dynamics>
          <spring_reference>0</spring_reference>
          <spring_stiffness>0</spring_stiffness>
        </dynamics>
      </axis>
    </joint>
    <link name='laser'>
      <pose relative_to='hokuyo_joint'>0 0 0 0 -0 0</pose>
      <inertial>
        <pose>0 0 0 0 -0 0</pose>
        <mass>0.13</mass>
        <inertia>
          <ixx>4e-06</ixx>
          <ixy>0</ixy>
          <ixz>0</ixz>
          <iyy>4e-06</iyy>
          <iyz>0</iyz>
          <izz>4e-06</izz>
        </inertia>
      </inertial>
      <collision name='laser_collision'>
        <pose>0 0 0 0 -0 0</pose>
        <geometry>
          <box>
            <size>0.1 0.1 0.1</size>
          </box>
        </geometry>
      </collision>
      <visual name='laser_visual'>
        <pose>0 0 0 0 -0 0</pose>
        <geometry>
          <mesh>
            <scale>1 1 1</scale>
            <uri>model://src_ackermann/meshes/hokuyo.dae</uri>
          </mesh>
        </geometry>
      </visual>
      <sensor name="lidar" type="ray">
        <pose>0 0 0 0 0 0</pose>
        <always_on>true</always_on>
        <visualize>true</visualize>
        <update_rate>10</update_rate>
        <ray>
          <scan>
            <horizontal>
              <samples>120</samples>
              <resolution>1.000000</resolution>
              <min_angle>-3.14159</min_angle>
              <max_angle>3.14159</max_angle>
            </horizontal>
          </scan>
          <range>
            <min>0.3</min>
            <max>15.0</max>
            <resolution>0.015</resolution>
          </range>
          <noise>
            <type>gaussian</type>
            <mean>0.0</mean>
            <stddev>0.01</stddev>
          </noise>
        </ray>
        <plugin name="scan" filename="libgazebo_ros_ray_sensor.so">
          <ros>
            <remapping>~/out:=scan</remapping>
          </ros>
          <output_type>sensor_msgs/LaserScan</output_type>
          <frame_name>laser</frame_name>
        </plugin>
      </sensor>
    </link>
    <joint name='left_rear_wheel_joint' type='revolute'>
      <pose relative_to='base_link'>0 0.1 0.05 1.5708 -0 0</pose>
      <parent>base_link</parent>
      <child>left_rear_wheel</child>
      <axis>
        <xyz>0 0 -1</xyz>
        <limit>
          <effort>10</effort>
          <velocity>100</velocity>
          <lower>-1e+16</lower>
          <upper>1e+16</upper>
        </limit>
        <dynamics>
          <spring_reference>0</spring_reference>
          <spring_stiffness>0</spring_stiffness>
        </dynamics>
      </axis>
    </joint>
    <link name='left_rear_wheel'>
      <pose relative_to='left_rear_wheel_joint'>0 0 0 0 -0 0</pose>
      <inertial>
        <pose>0 0 -0.0225 0 -0 0</pose>
        <mass>0.34055</mass>
        <inertia>
          <ixx>0.00026046</ixx>
          <ixy>0</ixy>
          <ixz>0</ixz>
          <iyy>0.00026046</iyy>
          <iyz>0</iyz>
          <izz>0.00041226</izz>
        </inertia>
      </inertial>
      <collision name='left_rear_wheel_collision'>
        <pose>0 0 -0.0225 0 -0 0</pose>
        <geometry>
          <cylinder>
            <length>0.045</length>
            <radius>0.05</radius>
          </cylinder>
        </geometry>
      </collision>
      <visual name='left_rear_wheel_visual'>
        <pose>0 0 0 0 -0 0</pose>
        <geometry>
          <mesh>
            <scale>1 1 1</scale>
            <uri>model://src_ackermann/meshes/left_rear_wheel.STL</uri>
          </mesh>
        </geometry>
      </visual>
    </link>
    <joint name='left_steering_hinge_joint' type='revolute'>
      <pose relative_to='base_link'>0.325 0.1 0.05 3.14159 1.57079 3.14159</pose>
      <parent>base_link</parent>
      <child>left_steering_hinge</child>
      <axis>
        <xyz>-1 0 0</xyz>
        <limit>
          <lower>-0.7853</lower>
          <upper>0.7853</upper>
          <effort>10</effort>
          <velocity>100</velocity>
        </limit>
        <dynamics>
          <spring_reference>0</spring_reference>
          <spring_stiffness>0</spring_stiffness>
        </dynamics>
      </axis>
    </joint>
    <link name='left_steering_hinge'>
      <pose relative_to='left_steering_hinge_joint'>0 0 0 0 -0 0</pose>
      <inertial>
        <pose>0 0 0 0 -0 0</pose>
        <mass>0.1</mass>
        <inertia>
          <ixx>4e-06</ixx>
          <ixy>0</ixy>
          <ixz>0</ixz>
          <iyy>4e-06</iyy>
          <iyz>0</iyz>
          <izz>4e-06</izz>
        </inertia>
      </inertial>
      <visual name='left_steering_hinge_visual'>
        <pose>0 0 0 0 -0 0</pose>
        <geometry>
          <mesh>
            <scale>1 1 1</scale>
            <uri>model://src_ackermann/meshes/left_steering_hinge.STL</uri>
          </mesh>
        </geometry>
      </visual>
    </link>
    <joint name='left_front_wheel_joint' type='revolute'>
      <pose relative_to='left_steering_hinge'>0 0 0 1.5708 -0 0</pose>
      <parent>left_steering_hinge</parent>
      <child>left_front_wheel</child>
      <axis>
        <xyz>0 0 -1</xyz>
        <limit>
          <effort>10</effort>
          <velocity>100</velocity>
          <lower>-1e+16</lower>
          <upper>1e+16</upper>
        </limit>
        <dynamics>
          <spring_reference>0</spring_reference>
          <spring_stiffness>0</spring_stiffness>
        </dynamics>
      </axis>
    </joint>
    <link name='left_front_wheel'>
      <pose relative_to='left_front_wheel_joint'>0 0 0 0 -0 0</pose>
      <inertial>
        <pose>0 0 -0.0225 0 -0 0</pose>
        <mass>0.34055</mass>
        <inertia>
          <ixx>0.00026046</ixx>
          <ixy>0</ixy>
          <ixz>0</ixz>
          <iyy>0.00026046</iyy>
          <iyz>0</iyz>
          <izz>0.00041226</izz>
        </inertia>
      </inertial>
      <collision name='left_front_wheel_collision'>
        <pose>0 0 -0.0225 0 -0 0</pose>
        <geometry>
          <cylinder>
            <length>0.045</length>
            <radius>0.05</radius>
          </cylinder>
        </geometry>
      </collision>
      <visual name='left_front_wheel_visual'>
        <pose>0 0 0 0 -0 0</pose>
        <geometry>
          <mesh>
            <scale>1 1 1</scale>
            <uri>model://src_ackermann/meshes/left_front_wheel.STL</uri>
          </mesh>
        </geometry>
      </visual>
    </link>
    <joint name='right_rear_wheel_joint' type='revolute'>
      <pose relative_to='base_link'>0 -0.1 0.05 1.5708 -0 0</pose>
      <parent>base_link</parent>
      <child>right_rear_wheel</child>
      <axis>
        <xyz>0 0 -1</xyz>
        <limit>
          <effort>10</effort>
          <velocity>100</velocity>
          <lower>-1e+16</lower>
          <upper>1e+16</upper>
        </limit>
        <dynamics>
          <spring_reference>0</spring_reference>
          <spring_stiffness>0</spring_stiffness>
        </dynamics>
      </axis>
    </joint>
    <link name='right_rear_wheel'>
      <pose relative_to='right_rear_wheel_joint'>0 0 0 0 -0 0</pose>
      <inertial>
        <pose>0 0 0.0225 0 -0 0</pose>
        <mass>0.34055</mass>
        <inertia>
          <ixx>0.00026046</ixx>
          <ixy>0</ixy>
          <ixz>0</ixz>
          <iyy>0.00026046</iyy>
          <iyz>0</iyz>
          <izz>0.00041226</izz>
        </inertia>
      </inertial>
      <collision name='right_rear_wheel_collision'>
        <pose>0 0 0.0225 0 -0 0</pose>
        <geometry>
          <cylinder>
            <length>0.045</length>
            <radius>0.05</radius>
          </cylinder>
        </geometry>
      </collision>
      <visual name='right_rear_wheel_visual'>
        <pose>0 0 0 0 -0 0</pose>
        <geometry>
          <mesh>
            <scale>1 1 1</scale>
            <uri>model://src_ackermann/meshes/right_rear_wheel.STL</uri>
          </mesh>
        </geometry>
      </visual>
    </link>
    <joint name='right_steering_hinge_joint' type='revolute'>
      <pose relative_to='base_link'>0.325 -0.1 0.05 3.14159 1.57079 3.14159</pose>
      <parent>base_link</parent>
      <child>right_steering_hinge</child>
      <axis>
        <xyz>-1 0 0</xyz>
        <limit>
          <effort>10</effort>
          <velocity>100</velocity>
          <lower>-1e+16</lower>
          <upper>1e+16</upper>
        </limit>
        <dynamics>
          <spring_reference>0</spring_reference>
          <spring_stiffness>0</spring_stiffness>
        </dynamics>
      </axis>
    </joint>
    <link name='right_steering_hinge'>
      <pose relative_to='right_steering_hinge_joint'>0 0 0 0 -0 0</pose>
      <inertial>
        <pose>0 0 0 0 -0 0</pose>
        <mass>0.1</mass>
        <inertia>
          <ixx>4e-06</ixx>
          <ixy>0</ixy>
          <ixz>0</ixz>
          <iyy>4e-06</iyy>
          <iyz>0</iyz>
          <izz>4e-06</izz>
        </inertia>
      </inertial>
      <visual name='right_steering_hinge_visual'>
        <pose>0 0 0 0 -0 0</pose>
        <geometry>
          <mesh>
            <scale>1 1 1</scale>
            <uri>model://src_ackermann/meshes/right_steering_hinge.STL</uri>
          </mesh>
        </geometry>
      </visual>
    </link>
    <joint name='right_front_wheel_joint' type='revolute'>
      <pose relative_to='right_steering_hinge'>0 0 0 1.5708 -0 0</pose>
      <parent>right_steering_hinge</parent>
      <child>right_front_wheel</child>
      <axis>
        <xyz>0 0 -1</xyz>
        <limit>
          <effort>10</effort>
          <velocity>100</velocity>
          <lower>-1e+16</lower>
          <upper>1e+16</upper>
        </limit>
        <dynamics>
          <spring_reference>0</spring_reference>
          <spring_stiffness>0</spring_stiffness>
        </dynamics>
      </axis>
    </joint>
    <link name='right_front_wheel'>
      <pose relative_to='right_front_wheel_joint'>0 0 0 0 -0 0</pose>
      <inertial>
        <pose>0 0 0.0225 0 -0 0</pose>
        <mass>0.34055</mass>
        <inertia>
          <ixx>0.00026046</ixx>
          <ixy>0</ixy>
          <ixz>0</ixz>
          <iyy>0.00026046</iyy>
          <iyz>0</iyz>
          <izz>0.00041226</izz>
        </inertia>
      </inertial>
      <collision name='right_front_wheel_collision'>
        <pose>0 0 0.0225 0 -0 0</pose>
        <geometry>
          <cylinder>
            <length>0.045</length>
            <radius>0.05</radius>
          </cylinder>
        </geometry>
      </collision>
      <visual name='right_front_wheel_visual'>
        <pose>0 0 0 0 -0 0</pose>
        <geometry>
          <mesh>
            <scale>1 1 1</scale>
            <uri>model://src_ackermann/meshes/right_front_wheel.STL</uri>
          </mesh>
        </geometry>
      </visual>
    </link>
    <joint name='zed_camera_joint' type='revolute'>
      <pose relative_to='base_link'>0.39 0 0.09 0 -0 0</pose>
      <parent>base_link</parent>
      <child>zed_camera_link</child>
      <axis>
        <xyz>0 0 1</xyz>
        <limit>
          <lower>-1e+16</lower>
          <upper>1e+16</upper>
        </limit>
        <dynamics>
          <spring_reference>0</spring_reference>
          <spring_stiffness>0</spring_stiffness>
        </dynamics>
      </axis>
    </joint>
    <link name='zed_camera_link'>
      <pose relative_to='zed_camera_joint'>0 0 0 0 -0 0</pose>
      <inertial>
        <pose>0 0 0 0 -0 0</pose>
        <mass>3e-05</mass>
        <inertia>
          <ixx>3.072e-06</ixx>
          <ixy>0</ixy>
          <ixz>0</ixz>
          <iyy>3e-06</iyy>
          <iyz>0</iyz>
          <izz>3.072e-06</izz>
        </inertia>
      </inertial>
      <collision name='zed_camera_link_collision'>
        <pose>0 0 0 0 -0 0</pose>
        <geometry>
          <box>
            <size>0.033 0.175 0.03</size>
          </box>
        </geometry>
      </collision>
      <visual name='zed_camera_link_visual'>
        <pose>0 0 0 0 -0 0</pose>
        <geometry>
          <box>
            <size>0.033 0.175 0.03</size>
          </box>
        </geometry>
      </visual>
    </link>
    <joint name='imu_joint' type='revolute'>
      <pose relative_to='zed_camera_link'>0.01 0 0 0 -0 0</pose>
      <parent>zed_camera_link</parent>
      <child>imu_link</child>
      <axis>
        <xyz>1 0 0</xyz>
        <limit>
          <lower>-1e+16</lower>
          <upper>1e+16</upper>
        </limit>
        <dynamics>
          <spring_reference>0</spring_reference>
          <spring_stiffness>0</spring_stiffness>
        </dynamics>
      </axis>
    </joint>
    <link name='imu_link'>
      <pose relative_to='imu_joint'>0 0 0 0 -0 0</pose>
      <inertial>
        <pose>0 0 0 0 -0 0</pose>
        <mass>0.01</mass>
        <inertia>
          <ixx>1</ixx>
          <ixy>0</ixy>
          <ixz>0</ixz>
          <iyy>1</iyy>
          <iyz>0</iyz>
          <izz>1</izz>
        </inertia>
      </inertial>
    </link>
  </model>
</sdf>
